2019/06/20 11:20:24 - INFO - 87 - _internal -  * Restarting with stat
2019/06/20 11:20:26 - WARNING - 87 - _internal -  * Debugger is active!
2019/06/20 11:20:26 - INFO - 87 - _internal -  * Debugger PIN: 154-804-553
2019/06/20 11:20:26 - INFO - 87 - _internal -  * Running on http://0.0.0.0:7777/ (Press CTRL+C to quit)
2019/06/20 11:20:27 - INFO - 85 - rank - object of type 'BaseQuery' has no len()
Traceback (most recent call last):
  File ".\Blog系统\Mini-Blog\view\rank.py", line 70, in rankComment
    resp_data['datacount'] = len(data)
TypeError: object of type 'BaseQuery' has no len()
2019/06/20 11:20:28 - INFO - 87 - _internal - 127.0.0.1 - - [20/Jun/2019 11:20:28] "GET /getRank/ HTTP/1.1" 200 -
2019/06/20 11:21:23 - INFO - 87 - _internal -  * Detected change in 'C:\\Users\\余委玲\\Desktop\\答辩\\Blog系统\\Mini-Blog\\view\\rank.py', reloading
2019/06/20 11:21:23 - INFO - 87 - _internal -  * Restarting with stat
2019/06/20 11:21:24 - WARNING - 87 - _internal -  * Debugger is active!
2019/06/20 11:21:24 - INFO - 87 - _internal -  * Debugger PIN: 154-804-553
2019/06/20 11:21:24 - INFO - 87 - _internal -  * Running on http://0.0.0.0:7777/ (Press CTRL+C to quit)
2019/06/20 11:21:30 - INFO - 87 - _internal -  * Detected change in 'C:\\Users\\余委玲\\Desktop\\答辩\\Blog系统\\Mini-Blog\\view\\rank.py', reloading
2019/06/20 11:21:30 - INFO - 87 - _internal -  * Restarting with stat
2019/06/20 11:21:31 - WARNING - 87 - _internal -  * Debugger is active!
2019/06/20 11:21:31 - INFO - 87 - _internal -  * Debugger PIN: 154-804-553
2019/06/20 11:21:31 - INFO - 87 - _internal -  * Running on http://0.0.0.0:7777/ (Press CTRL+C to quit)
2019/06/20 11:21:32 - INFO - 86 - rank - object of type 'BaseQuery' has no len()
Traceback (most recent call last):
  File ".\Blog系统\Mini-Blog\view\rank.py", line 71, in rankComment
    resp_data['datacount'] = len(data)
TypeError: object of type 'BaseQuery' has no len()
2019/06/20 11:21:32 - INFO - 87 - _internal - 127.0.0.1 - - [20/Jun/2019 11:21:32] "GET /getRank/ HTTP/1.1" 500 -
2019/06/20 11:21:52 - INFO - 86 - rank - object of type 'BaseQuery' has no len()
Traceback (most recent call last):
  File ".\Blog系统\Mini-Blog\view\rank.py", line 71, in rankComment
    resp_data['datacount'] = len(data)
TypeError: object of type 'BaseQuery' has no len()
2019/06/20 11:21:52 - INFO - 87 - _internal - 127.0.0.1 - - [20/Jun/2019 11:21:52] "GET /getRank/ HTTP/1.1" 500 -
2019/06/20 11:22:15 - INFO - 87 - _internal -  * Detected change in 'C:\\Users\\余委玲\\Desktop\\答辩\\Blog系统\\Mini-Blog\\view\\rank.py', reloading
2019/06/20 11:22:15 - INFO - 87 - _internal -  * Restarting with stat
2019/06/20 11:22:17 - WARNING - 87 - _internal -  * Debugger is active!
2019/06/20 11:22:17 - INFO - 87 - _internal -  * Debugger PIN: 154-804-553
2019/06/20 11:22:17 - INFO - 87 - _internal -  * Running on http://0.0.0.0:7777/ (Press CTRL+C to quit)
2019/06/20 11:22:21 - INFO - 87 - _internal - 127.0.0.1 - - [20/Jun/2019 11:22:21] "GET /getRank/ HTTP/1.1" 200 -
2019/06/20 11:22:33 - INFO - 87 - _internal -  * Detected change in 'C:\\Users\\余委玲\\Desktop\\答辩\\Blog系统\\Mini-Blog\\view\\rank.py', reloading
2019/06/20 11:22:33 - INFO - 87 - _internal -  * Restarting with stat
2019/06/20 11:22:35 - WARNING - 87 - _internal -  * Debugger is active!
2019/06/20 11:22:35 - INFO - 87 - _internal -  * Debugger PIN: 154-804-553
2019/06/20 11:22:35 - INFO - 87 - _internal -  * Running on http://0.0.0.0:7777/ (Press CTRL+C to quit)
2019/06/20 11:22:37 - INFO - 87 - _internal -  * Detected change in 'C:\\Users\\余委玲\\Desktop\\答辩\\Blog系统\\Mini-Blog\\view\\rank.py', reloading
2019/06/20 11:22:37 - INFO - 87 - _internal -  * Restarting with stat
2019/06/20 11:22:39 - WARNING - 87 - _internal -  * Debugger is active!
2019/06/20 11:22:39 - INFO - 87 - _internal -  * Debugger PIN: 154-804-553
2019/06/20 11:22:39 - INFO - 87 - _internal -  * Running on http://0.0.0.0:7777/ (Press CTRL+C to quit)
2019/06/20 11:22:41 - INFO - 87 - _internal - 127.0.0.1 - - [20/Jun/2019 11:22:41] "GET /getRank/ HTTP/1.1" 200 -
2019/06/20 11:23:07 - INFO - 87 - _internal -  * Detected change in 'C:\\Users\\余委玲\\Desktop\\答辩\\Blog系统\\Mini-Blog\\view\\rank.py', reloading
2019/06/20 11:23:07 - INFO - 87 - _internal -  * Restarting with stat
2019/06/20 11:23:08 - WARNING - 87 - _internal -  * Debugger is active!
2019/06/20 11:23:08 - INFO - 87 - _internal -  * Debugger PIN: 154-804-553
2019/06/20 11:23:08 - INFO - 87 - _internal -  * Running on http://0.0.0.0:7777/ (Press CTRL+C to quit)
2019/06/20 11:23:33 - INFO - 87 - _internal -  * Detected change in 'C:\\Users\\余委玲\\Desktop\\答辩\\Blog系统\\Mini-Blog\\view\\rank.py', reloading
2019/06/20 11:23:33 - INFO - 87 - _internal -  * Restarting with stat
2019/06/20 11:23:35 - WARNING - 87 - _internal -  * Debugger is active!
2019/06/20 11:23:35 - INFO - 87 - _internal -  * Debugger PIN: 154-804-553
2019/06/20 11:23:35 - INFO - 87 - _internal -  * Running on http://0.0.0.0:7777/ (Press CTRL+C to quit)
2019/06/20 11:23:38 - INFO - 87 - _internal -  * Detected change in 'C:\\Users\\余委玲\\Desktop\\答辩\\Blog系统\\Mini-Blog\\view\\rank.py', reloading
2019/06/20 11:23:38 - INFO - 87 - _internal -  * Restarting with stat
2019/06/20 11:23:40 - WARNING - 87 - _internal -  * Debugger is active!
2019/06/20 11:23:40 - INFO - 87 - _internal -  * Debugger PIN: 154-804-553
2019/06/20 11:23:40 - INFO - 87 - _internal -  * Running on http://0.0.0.0:7777/ (Press CTRL+C to quit)
2019/06/20 11:23:57 - INFO - 87 - _internal -  * Restarting with stat
2019/06/20 11:23:59 - WARNING - 87 - _internal -  * Debugger is active!
2019/06/20 11:23:59 - INFO - 87 - _internal -  * Debugger PIN: 154-804-553
2019/06/20 11:23:59 - INFO - 87 - _internal -  * Running on http://0.0.0.0:7777/ (Press CTRL+C to quit)
2019/06/20 11:24:07 - INFO - 87 - _internal - 127.0.0.1 - - [20/Jun/2019 11:24:07] "GET /rank/date/ HTTP/1.1" 200 -
2019/06/20 11:24:19 - INFO - 87 - _internal -  * Detected change in 'C:\\Users\\余委玲\\Desktop\\答辩\\Blog系统\\Mini-Blog\\view\\rank.py', reloading
2019/06/20 11:24:20 - INFO - 87 - _internal -  * Restarting with stat
2019/06/20 11:24:21 - WARNING - 87 - _internal -  * Debugger is active!
2019/06/20 11:24:21 - INFO - 87 - _internal -  * Debugger PIN: 154-804-553
2019/06/20 11:24:21 - INFO - 87 - _internal -  * Running on http://0.0.0.0:7777/ (Press CTRL+C to quit)
2019/06/20 11:24:24 - INFO - 87 - _internal - 127.0.0.1 - - [20/Jun/2019 11:24:24] "GET /rank/date/ HTTP/1.1" 200 -
2019/06/20 11:24:31 - INFO - 87 - _internal -  * Detected change in 'C:\\Users\\余委玲\\Desktop\\答辩\\Blog系统\\Mini-Blog\\view\\rank.py', reloading
2019/06/20 11:24:31 - INFO - 87 - _internal -  * Restarting with stat
2019/06/20 11:24:33 - WARNING - 87 - _internal -  * Debugger is active!
2019/06/20 11:24:33 - INFO - 87 - _internal -  * Debugger PIN: 154-804-553
2019/06/20 11:24:33 - INFO - 87 - _internal -  * Running on http://0.0.0.0:7777/ (Press CTRL+C to quit)
2019/06/20 11:25:38 - INFO - 87 - _internal -  * Detected change in 'C:\\Users\\余委玲\\Desktop\\答辩\\Blog系统\\Mini-Blog\\view\\rank.py', reloading
2019/06/20 11:25:38 - INFO - 87 - _internal -  * Restarting with stat
2019/06/20 11:43:58 - INFO - 87 - _internal -  * Restarting with stat
2019/06/20 11:44:00 - WARNING - 87 - _internal -  * Debugger is active!
2019/06/20 11:44:00 - INFO - 87 - _internal -  * Debugger PIN: 154-804-553
2019/06/20 11:44:00 - INFO - 87 - _internal -  * Running on http://0.0.0.0:7777/ (Press CTRL+C to quit)
2019/06/20 11:44:02 - INFO - 87 - _internal - 127.0.0.1 - - [20/Jun/2019 11:44:02] "GET /rank/date/ HTTP/1.1" 500 -
2019/06/20 11:44:11 - INFO - 87 - _internal -  * Restarting with stat
2019/06/20 11:44:12 - WARNING - 87 - _internal -  * Debugger is active!
2019/06/20 11:44:12 - INFO - 87 - _internal -  * Debugger PIN: 154-804-553
2019/06/20 11:44:12 - INFO - 87 - _internal -  * Running on http://0.0.0.0:7777/ (Press CTRL+C to quit)
2019/06/20 11:44:15 - INFO - 87 - _internal - 127.0.0.1 - - [20/Jun/2019 11:44:15] "GET /rank/date/ HTTP/1.1" 500 -
2019/06/20 11:44:17 - INFO - 87 - _internal - 127.0.0.1 - - [20/Jun/2019 11:44:17] "GET /rank/date/ HTTP/1.1" 500 -
2019/06/20 11:44:19 - INFO - 87 - _internal - 127.0.0.1 - - [20/Jun/2019 11:44:19] "GET /rank/date/ HTTP/1.1" 500 -
2019/06/20 11:44:21 - INFO - 87 - _internal - 127.0.0.1 - - [20/Jun/2019 11:44:21] "GET /rank/date/ HTTP/1.1" 500 -
2019/06/20 11:45:58 - INFO - 87 - _internal -  * Restarting with stat
2019/06/20 11:46:00 - WARNING - 87 - _internal -  * Debugger is active!
2019/06/20 11:46:00 - INFO - 87 - _internal -  * Debugger PIN: 154-804-553
2019/06/20 11:46:00 - INFO - 87 - _internal -  * Running on http://0.0.0.0:7777/ (Press CTRL+C to quit)
2019/06/20 11:46:05 - INFO - 87 - _internal - 127.0.0.1 - - [20/Jun/2019 11:46:05] "GET /rank/date/ HTTP/1.1" 200 -
2019/06/20 11:46:56 - INFO - 87 - _internal -  * Detected change in 'C:\\Users\\余委玲\\Desktop\\答辩\\Blog系统\\Mini-Blog\\view\\rank.py', reloading
2019/06/20 11:46:56 - INFO - 87 - _internal -  * Restarting with stat
2019/06/20 11:46:58 - WARNING - 87 - _internal -  * Debugger is active!
2019/06/20 11:46:58 - INFO - 87 - _internal -  * Debugger PIN: 154-804-553
2019/06/20 11:46:58 - INFO - 87 - _internal -  * Running on http://0.0.0.0:7777/ (Press CTRL+C to quit)
2019/06/20 11:47:02 - INFO - 87 - _internal - 127.0.0.1 - - [20/Jun/2019 11:47:02] "GET /rank/date/ HTTP/1.1" 200 -
2019/06/20 11:47:46 - INFO - 87 - _internal -  * Detected change in 'C:\\Users\\余委玲\\Desktop\\答辩\\Blog系统\\Mini-Blog\\view\\rank.py', reloading
2019/06/20 11:47:46 - INFO - 87 - _internal -  * Restarting with stat
2019/06/20 11:47:48 - WARNING - 87 - _internal -  * Debugger is active!
2019/06/20 11:47:48 - INFO - 87 - _internal -  * Debugger PIN: 154-804-553
2019/06/20 11:47:48 - INFO - 87 - _internal -  * Running on http://0.0.0.0:7777/ (Press CTRL+C to quit)
2019/06/20 11:49:17 - INFO - 87 - _internal -  * Detected change in 'C:\\Users\\余委玲\\Desktop\\答辩\\Blog系统\\Mini-Blog\\view\\rank.py', reloading
2019/06/20 11:49:17 - INFO - 87 - _internal -  * Restarting with stat
2019/06/20 11:49:18 - WARNING - 87 - _internal -  * Debugger is active!
2019/06/20 11:49:18 - INFO - 87 - _internal -  * Debugger PIN: 154-804-553
2019/06/20 11:49:18 - INFO - 87 - _internal -  * Running on http://0.0.0.0:7777/ (Press CTRL+C to quit)
2019/06/22 16:49:02 - INFO - 87 - _internal -  * Restarting with stat
2019/06/22 16:49:03 - WARNING - 87 - _internal -  * Debugger is active!
2019/06/22 16:49:03 - INFO - 87 - _internal -  * Debugger PIN: 154-804-553
2019/06/22 16:49:03 - INFO - 87 - _internal -  * Running on http://0.0.0.0:7777/ (Press CTRL+C to quit)
2019/06/22 16:49:10 - INFO - 87 - _internal - 127.0.0.1 - - [22/Jun/2019 16:49:10] "GET /getRank/ HTTP/1.1" 200 -
2019/06/22 16:49:11 - INFO - 87 - _internal - 127.0.0.1 - - [22/Jun/2019 16:49:11] "GET /getRank/ HTTP/1.1" 200 -
2019/06/22 16:49:13 - INFO - 87 - _internal - 127.0.0.1 - - [22/Jun/2019 16:49:13] "GET /getRank/ HTTP/1.1" 200 -
2019/06/22 16:50:17 - INFO - 87 - _internal - 127.0.0.1 - - [22/Jun/2019 16:50:17] "GET /getRank/ HTTP/1.1" 200 -
2019/06/22 16:50:41 - INFO - 87 - _internal - 127.0.0.1 - - [22/Jun/2019 16:50:41] "GET /getRank/ HTTP/1.1" 200 -
2019/06/22 16:51:04 - INFO - 87 - _internal - 127.0.0.1 - - [22/Jun/2019 16:51:04] "GET /getRank/ HTTP/1.1" 200 -
2019/06/22 16:53:11 - INFO - 87 - _internal -  * Detected change in 'C:\\Users\\余委玲\\Desktop\\答辩\\Blog系统\\Mini-Blog\\view\\rank.py', reloading
2019/06/22 16:53:11 - INFO - 87 - _internal -  * Restarting with stat
2019/06/22 16:53:15 - WARNING - 87 - _internal -  * Debugger is active!
2019/06/22 16:53:15 - INFO - 87 - _internal -  * Debugger PIN: 154-804-553
2019/06/22 16:53:15 - INFO - 87 - _internal -  * Running on http://0.0.0.0:7777/ (Press CTRL+C to quit)
2019/06/22 16:53:49 - INFO - 87 - _internal - 127.0.0.1 - - [22/Jun/2019 16:53:49] "GET /getRank/ HTTP/1.1" 200 -
2019/06/22 16:54:06 - INFO - 87 - _internal - 127.0.0.1 - - [22/Jun/2019 16:54:06] "GET /getRank/ HTTP/1.1" 200 -
2019/06/22 16:54:33 - INFO - 87 - _internal -  * Restarting with stat
2019/06/22 16:54:34 - WARNING - 87 - _internal -  * Debugger is active!
2019/06/22 16:54:34 - INFO - 87 - _internal -  * Debugger PIN: 154-804-553
2019/06/22 16:54:34 - INFO - 87 - _internal -  * Running on http://0.0.0.0:7777/ (Press CTRL+C to quit)
2019/06/22 16:54:40 - INFO - 87 - _internal - 127.0.0.1 - - [22/Jun/2019 16:54:40] "GET /getRank/ HTTP/1.1" 200 -
2019/06/22 16:55:13 - INFO - 87 - _internal - 127.0.0.1 - - [22/Jun/2019 16:55:13] "GET /getRank/ HTTP/1.1" 200 -
2019/06/22 16:55:19 - INFO - 87 - _internal - 127.0.0.1 - - [22/Jun/2019 16:55:19] "GET /getRank/ HTTP/1.1" 200 -
2019/06/22 16:55:24 - INFO - 87 - _internal - 127.0.0.1 - - [22/Jun/2019 16:55:24] "GET /getRank/ HTTP/1.1" 200 -
2019/06/22 16:55:43 - INFO - 87 - _internal -  * Restarting with stat
2019/06/22 16:55:44 - WARNING - 87 - _internal -  * Debugger is active!
2019/06/22 16:55:44 - INFO - 87 - _internal -  * Debugger PIN: 154-804-553
2019/06/22 16:55:44 - INFO - 87 - _internal -  * Running on http://0.0.0.0:7777/ (Press CTRL+C to quit)
2019/06/22 16:55:48 - INFO - 87 - _internal - 127.0.0.1 - - [22/Jun/2019 16:55:48] "GET /getRank/ HTTP/1.1" 200 -
2019/06/22 16:55:57 - INFO - 87 - _internal -  * Detected change in 'C:\\Users\\余委玲\\Desktop\\答辩\\Blog系统\\Mini-Blog\\view\\rank.py', reloading
2019/06/22 16:55:57 - INFO - 87 - _internal -  * Restarting with stat
2019/06/22 16:56:01 - INFO - 87 - _internal -  * Restarting with stat
2019/06/22 16:56:01 - WARNING - 87 - _internal -  * Debugger is active!
2019/06/22 16:56:02 - INFO - 87 - _internal -  * Debugger PIN: 154-804-553
2019/06/22 16:56:02 - INFO - 87 - _internal -  * Running on http://0.0.0.0:7777/ (Press CTRL+C to quit)
2019/06/22 16:56:05 - INFO - 87 - _internal - 127.0.0.1 - - [22/Jun/2019 16:56:05] "GET /getRank/ HTTP/1.1" 200 -
2019/06/22 16:56:13 - INFO - 87 - _internal - 127.0.0.1 - - [22/Jun/2019 16:56:13] "GET /getRank/ HTTP/1.1" 200 -
2019/06/22 17:01:14 - INFO - 87 - _internal - 127.0.0.1 - - [22/Jun/2019 17:01:14] "GET /getRank/ HTTP/1.1" 200 -
2019/06/22 21:18:37 - INFO - 87 - _internal -  * Detected change in 'C:\\Users\\余委玲\\Desktop\\答辩\\Blog系统\\Mini-Blog\\view\\rank.py', reloading
2019/06/22 21:18:37 - INFO - 87 - _internal -  * Restarting with stat
2019/06/22 21:18:43 - INFO - 87 - _internal -  * Restarting with stat
2019/06/22 21:18:46 - WARNING - 87 - _internal -  * Debugger is active!
2019/06/22 21:18:46 - INFO - 87 - _internal -  * Debugger PIN: 154-804-553
2019/06/22 21:18:46 - INFO - 87 - _internal -  * Running on http://0.0.0.0:7777/ (Press CTRL+C to quit)
2019/06/22 21:19:22 - INFO - 87 - _internal - 127.0.0.1 - - [22/Jun/2019 21:19:22] "GET /getRank/ HTTP/1.1" 200 -
2019/06/22 21:19:28 - INFO - 87 - _internal - 127.0.0.1 - - [22/Jun/2019 21:19:28] "GET /getRank/ HTTP/1.1" 200 -
2019/06/22 21:24:29 - INFO - 87 - _internal - 127.0.0.1 - - [22/Jun/2019 21:24:29] "GET /getRank/ HTTP/1.1" 200 -
2019/06/22 23:39:21 - INFO - 86 - rank - (mysql.connector.errors.OperationalError) MySQL Connection not available. [SQL: 'SELECT `Blog`.blogid AS `Blog_blogid`, `Blog`.title AS `Blog_title`, `Blog`.author AS `Blog_author`, `Blog`.content AS `Blog_content`, `Blog`.sub_date AS `Blog_sub_date`, `Blog`.comment_num AS `Blog_comment_num` \nFROM `Blog` ORDER BY `Blog`.comment_num \n LIMIT %(param_1)s'] [parameters: [{}]]
Traceback (most recent call last):
  File "C:\LeoLee\Anaconda3\lib\site-packages\sqlalchemy\engine\base.py", line 1116, in _execute_context
    context = constructor(dialect, self, conn, *args)
  File "C:\LeoLee\Anaconda3\lib\site-packages\sqlalchemy\engine\default.py", line 598, in _init_compiled
    self.cursor = self.create_cursor()
  File "C:\LeoLee\Anaconda3\lib\site-packages\sqlalchemy\engine\default.py", line 821, in create_cursor
    return self._dbapi_connection.cursor()
  File "C:\LeoLee\Anaconda3\lib\site-packages\sqlalchemy\pool.py", line 926, in cursor
    return self.connection.cursor(*args, **kwargs)
  File "C:\LeoLee\Anaconda3\lib\site-packages\mysql\connector\connection.py", line 809, in cursor
    raise errors.OperationalError("MySQL Connection not available.")
mysql.connector.errors.OperationalError: MySQL Connection not available.

The above exception was the direct cause of the following exception:

Traceback (most recent call last):
  File ".\view\rank.py", line 66, in rankComment
    data = Blog.query.order_by(Blog.comment_num).limit(10).all()
  File "C:\LeoLee\Anaconda3\lib\site-packages\sqlalchemy\orm\query.py", line 2703, in all
    return list(self)
  File "C:\LeoLee\Anaconda3\lib\site-packages\sqlalchemy\orm\query.py", line 2855, in __iter__
    return self._execute_and_instances(context)
  File "C:\LeoLee\Anaconda3\lib\site-packages\sqlalchemy\orm\query.py", line 2878, in _execute_and_instances
    result = conn.execute(querycontext.statement, self._params)
  File "C:\LeoLee\Anaconda3\lib\site-packages\sqlalchemy\engine\base.py", line 945, in execute
    return meth(self, multiparams, params)
  File "C:\LeoLee\Anaconda3\lib\site-packages\sqlalchemy\sql\elements.py", line 263, in _execute_on_connection
    return connection._execute_clauseelement(self, multiparams, params)
  File "C:\LeoLee\Anaconda3\lib\site-packages\sqlalchemy\engine\base.py", line 1053, in _execute_clauseelement
    compiled_sql, distilled_params
  File "C:\LeoLee\Anaconda3\lib\site-packages\sqlalchemy\engine\base.py", line 1121, in _execute_context
    None, None)
  File "C:\LeoLee\Anaconda3\lib\site-packages\sqlalchemy\engine\base.py", line 1402, in _handle_dbapi_exception
    exc_info
  File "C:\LeoLee\Anaconda3\lib\site-packages\sqlalchemy\util\compat.py", line 203, in raise_from_cause
    reraise(type(exception), exception, tb=exc_tb, cause=cause)
  File "C:\LeoLee\Anaconda3\lib\site-packages\sqlalchemy\util\compat.py", line 186, in reraise
    raise value.with_traceback(tb)
  File "C:\LeoLee\Anaconda3\lib\site-packages\sqlalchemy\engine\base.py", line 1116, in _execute_context
    context = constructor(dialect, self, conn, *args)
  File "C:\LeoLee\Anaconda3\lib\site-packages\sqlalchemy\engine\default.py", line 598, in _init_compiled
    self.cursor = self.create_cursor()
  File "C:\LeoLee\Anaconda3\lib\site-packages\sqlalchemy\engine\default.py", line 821, in create_cursor
    return self._dbapi_connection.cursor()
  File "C:\LeoLee\Anaconda3\lib\site-packages\sqlalchemy\pool.py", line 926, in cursor
    return self.connection.cursor(*args, **kwargs)
  File "C:\LeoLee\Anaconda3\lib\site-packages\mysql\connector\connection.py", line 809, in cursor
    raise errors.OperationalError("MySQL Connection not available.")
sqlalchemy.exc.OperationalError: (mysql.connector.errors.OperationalError) MySQL Connection not available. [SQL: 'SELECT `Blog`.blogid AS `Blog_blogid`, `Blog`.title AS `Blog_title`, `Blog`.author AS `Blog_author`, `Blog`.content AS `Blog_content`, `Blog`.sub_date AS `Blog_sub_date`, `Blog`.comment_num AS `Blog_comment_num` \nFROM `Blog` ORDER BY `Blog`.comment_num \n LIMIT %(param_1)s'] [parameters: [{}]]
2019/06/22 23:39:21 - INFO - 87 - _internal - 127.0.0.1 - - [22/Jun/2019 23:39:21] "GET /getRank/ HTTP/1.1" 200 -
2019/06/22 23:39:23 - INFO - 86 - rank - (sqlalchemy.exc.InvalidRequestError) Can't reconnect until invalid transaction is rolled back [SQL: 'SELECT `Blog`.blogid AS `Blog_blogid`, `Blog`.title AS `Blog_title`, `Blog`.author AS `Blog_author`, `Blog`.content AS `Blog_content`, `Blog`.sub_date AS `Blog_sub_date`, `Blog`.comment_num AS `Blog_comment_num` \nFROM `Blog` ORDER BY `Blog`.comment_num \n LIMIT %(param_1)s'] [parameters: [{}]]
Traceback (most recent call last):
  File "C:\LeoLee\Anaconda3\lib\site-packages\sqlalchemy\engine\base.py", line 1112, in _execute_context
    conn = self.__connection
AttributeError: 'Connection' object has no attribute '_Connection__connection'

During handling of the above exception, another exception occurred:

Traceback (most recent call last):
  File "C:\LeoLee\Anaconda3\lib\site-packages\sqlalchemy\engine\base.py", line 1114, in _execute_context
    conn = self._revalidate_connection()
  File "C:\LeoLee\Anaconda3\lib\site-packages\sqlalchemy\engine\base.py", line 424, in _revalidate_connection
    "Can't reconnect until invalid "
sqlalchemy.exc.InvalidRequestError: Can't reconnect until invalid transaction is rolled back

The above exception was the direct cause of the following exception:

Traceback (most recent call last):
  File ".\view\rank.py", line 66, in rankComment
    data = Blog.query.order_by(Blog.comment_num).limit(10).all()
  File "C:\LeoLee\Anaconda3\lib\site-packages\sqlalchemy\orm\query.py", line 2703, in all
    return list(self)
  File "C:\LeoLee\Anaconda3\lib\site-packages\sqlalchemy\orm\query.py", line 2855, in __iter__
    return self._execute_and_instances(context)
  File "C:\LeoLee\Anaconda3\lib\site-packages\sqlalchemy\orm\query.py", line 2878, in _execute_and_instances
    result = conn.execute(querycontext.statement, self._params)
  File "C:\LeoLee\Anaconda3\lib\site-packages\sqlalchemy\engine\base.py", line 945, in execute
    return meth(self, multiparams, params)
  File "C:\LeoLee\Anaconda3\lib\site-packages\sqlalchemy\sql\elements.py", line 263, in _execute_on_connection
    return connection._execute_clauseelement(self, multiparams, params)
  File "C:\LeoLee\Anaconda3\lib\site-packages\sqlalchemy\engine\base.py", line 1053, in _execute_clauseelement
    compiled_sql, distilled_params
  File "C:\LeoLee\Anaconda3\lib\site-packages\sqlalchemy\engine\base.py", line 1121, in _execute_context
    None, None)
  File "C:\LeoLee\Anaconda3\lib\site-packages\sqlalchemy\engine\base.py", line 1402, in _handle_dbapi_exception
    exc_info
  File "C:\LeoLee\Anaconda3\lib\site-packages\sqlalchemy\util\compat.py", line 203, in raise_from_cause
    reraise(type(exception), exception, tb=exc_tb, cause=cause)
  File "C:\LeoLee\Anaconda3\lib\site-packages\sqlalchemy\util\compat.py", line 186, in reraise
    raise value.with_traceback(tb)
  File "C:\LeoLee\Anaconda3\lib\site-packages\sqlalchemy\engine\base.py", line 1114, in _execute_context
    conn = self._revalidate_connection()
  File "C:\LeoLee\Anaconda3\lib\site-packages\sqlalchemy\engine\base.py", line 424, in _revalidate_connection
    "Can't reconnect until invalid "
sqlalchemy.exc.StatementError: (sqlalchemy.exc.InvalidRequestError) Can't reconnect until invalid transaction is rolled back [SQL: 'SELECT `Blog`.blogid AS `Blog_blogid`, `Blog`.title AS `Blog_title`, `Blog`.author AS `Blog_author`, `Blog`.content AS `Blog_content`, `Blog`.sub_date AS `Blog_sub_date`, `Blog`.comment_num AS `Blog_comment_num` \nFROM `Blog` ORDER BY `Blog`.comment_num \n LIMIT %(param_1)s'] [parameters: [{}]]
2019/06/22 23:39:23 - INFO - 87 - _internal - 127.0.0.1 - - [22/Jun/2019 23:39:23] "GET /getRank/ HTTP/1.1" 200 -
2019/06/22 23:39:27 - INFO - 86 - rank - (sqlalchemy.exc.InvalidRequestError) Can't reconnect until invalid transaction is rolled back [SQL: 'SELECT `Blog`.blogid AS `Blog_blogid`, `Blog`.title AS `Blog_title`, `Blog`.author AS `Blog_author`, `Blog`.content AS `Blog_content`, `Blog`.sub_date AS `Blog_sub_date`, `Blog`.comment_num AS `Blog_comment_num` \nFROM `Blog` ORDER BY `Blog`.comment_num \n LIMIT %(param_1)s'] [parameters: [{}]]
Traceback (most recent call last):
  File "C:\LeoLee\Anaconda3\lib\site-packages\sqlalchemy\engine\base.py", line 1112, in _execute_context
    conn = self.__connection
AttributeError: 'Connection' object has no attribute '_Connection__connection'

During handling of the above exception, another exception occurred:

Traceback (most recent call last):
  File "C:\LeoLee\Anaconda3\lib\site-packages\sqlalchemy\engine\base.py", line 1114, in _execute_context
    conn = self._revalidate_connection()
  File "C:\LeoLee\Anaconda3\lib\site-packages\sqlalchemy\engine\base.py", line 424, in _revalidate_connection
    "Can't reconnect until invalid "
sqlalchemy.exc.InvalidRequestError: Can't reconnect until invalid transaction is rolled back

The above exception was the direct cause of the following exception:

Traceback (most recent call last):
  File ".\view\rank.py", line 66, in rankComment
    data = Blog.query.order_by(Blog.comment_num).limit(10).all()
  File "C:\LeoLee\Anaconda3\lib\site-packages\sqlalchemy\orm\query.py", line 2703, in all
    return list(self)
  File "C:\LeoLee\Anaconda3\lib\site-packages\sqlalchemy\orm\query.py", line 2855, in __iter__
    return self._execute_and_instances(context)
  File "C:\LeoLee\Anaconda3\lib\site-packages\sqlalchemy\orm\query.py", line 2878, in _execute_and_instances
    result = conn.execute(querycontext.statement, self._params)
  File "C:\LeoLee\Anaconda3\lib\site-packages\sqlalchemy\engine\base.py", line 945, in execute
    return meth(self, multiparams, params)
  File "C:\LeoLee\Anaconda3\lib\site-packages\sqlalchemy\sql\elements.py", line 263, in _execute_on_connection
    return connection._execute_clauseelement(self, multiparams, params)
  File "C:\LeoLee\Anaconda3\lib\site-packages\sqlalchemy\engine\base.py", line 1053, in _execute_clauseelement
    compiled_sql, distilled_params
  File "C:\LeoLee\Anaconda3\lib\site-packages\sqlalchemy\engine\base.py", line 1121, in _execute_context
    None, None)
  File "C:\LeoLee\Anaconda3\lib\site-packages\sqlalchemy\engine\base.py", line 1402, in _handle_dbapi_exception
    exc_info
  File "C:\LeoLee\Anaconda3\lib\site-packages\sqlalchemy\util\compat.py", line 203, in raise_from_cause
    reraise(type(exception), exception, tb=exc_tb, cause=cause)
  File "C:\LeoLee\Anaconda3\lib\site-packages\sqlalchemy\util\compat.py", line 186, in reraise
    raise value.with_traceback(tb)
  File "C:\LeoLee\Anaconda3\lib\site-packages\sqlalchemy\engine\base.py", line 1114, in _execute_context
    conn = self._revalidate_connection()
  File "C:\LeoLee\Anaconda3\lib\site-packages\sqlalchemy\engine\base.py", line 424, in _revalidate_connection
    "Can't reconnect until invalid "
sqlalchemy.exc.StatementError: (sqlalchemy.exc.InvalidRequestError) Can't reconnect until invalid transaction is rolled back [SQL: 'SELECT `Blog`.blogid AS `Blog_blogid`, `Blog`.title AS `Blog_title`, `Blog`.author AS `Blog_author`, `Blog`.content AS `Blog_content`, `Blog`.sub_date AS `Blog_sub_date`, `Blog`.comment_num AS `Blog_comment_num` \nFROM `Blog` ORDER BY `Blog`.comment_num \n LIMIT %(param_1)s'] [parameters: [{}]]
2019/06/22 23:39:27 - INFO - 87 - _internal - 127.0.0.1 - - [22/Jun/2019 23:39:27] "GET /getRank/ HTTP/1.1" 200 -
2019/06/22 23:39:38 - INFO - 86 - rank - (sqlalchemy.exc.InvalidRequestError) Can't reconnect until invalid transaction is rolled back [SQL: 'SELECT `Blog`.blogid AS `Blog_blogid`, `Blog`.title AS `Blog_title`, `Blog`.author AS `Blog_author`, `Blog`.content AS `Blog_content`, `Blog`.sub_date AS `Blog_sub_date`, `Blog`.comment_num AS `Blog_comment_num` \nFROM `Blog` ORDER BY `Blog`.comment_num \n LIMIT %(param_1)s'] [parameters: [{}]]
Traceback (most recent call last):
  File "C:\LeoLee\Anaconda3\lib\site-packages\sqlalchemy\engine\base.py", line 1112, in _execute_context
    conn = self.__connection
AttributeError: 'Connection' object has no attribute '_Connection__connection'

During handling of the above exception, another exception occurred:

Traceback (most recent call last):
  File "C:\LeoLee\Anaconda3\lib\site-packages\sqlalchemy\engine\base.py", line 1114, in _execute_context
    conn = self._revalidate_connection()
  File "C:\LeoLee\Anaconda3\lib\site-packages\sqlalchemy\engine\base.py", line 424, in _revalidate_connection
    "Can't reconnect until invalid "
sqlalchemy.exc.InvalidRequestError: Can't reconnect until invalid transaction is rolled back

The above exception was the direct cause of the following exception:

Traceback (most recent call last):
  File ".\view\rank.py", line 66, in rankComment
    data = Blog.query.order_by(Blog.comment_num).limit(10).all()
  File "C:\LeoLee\Anaconda3\lib\site-packages\sqlalchemy\orm\query.py", line 2703, in all
    return list(self)
  File "C:\LeoLee\Anaconda3\lib\site-packages\sqlalchemy\orm\query.py", line 2855, in __iter__
    return self._execute_and_instances(context)
  File "C:\LeoLee\Anaconda3\lib\site-packages\sqlalchemy\orm\query.py", line 2878, in _execute_and_instances
    result = conn.execute(querycontext.statement, self._params)
  File "C:\LeoLee\Anaconda3\lib\site-packages\sqlalchemy\engine\base.py", line 945, in execute
    return meth(self, multiparams, params)
  File "C:\LeoLee\Anaconda3\lib\site-packages\sqlalchemy\sql\elements.py", line 263, in _execute_on_connection
    return connection._execute_clauseelement(self, multiparams, params)
  File "C:\LeoLee\Anaconda3\lib\site-packages\sqlalchemy\engine\base.py", line 1053, in _execute_clauseelement
    compiled_sql, distilled_params
  File "C:\LeoLee\Anaconda3\lib\site-packages\sqlalchemy\engine\base.py", line 1121, in _execute_context
    None, None)
  File "C:\LeoLee\Anaconda3\lib\site-packages\sqlalchemy\engine\base.py", line 1402, in _handle_dbapi_exception
    exc_info
  File "C:\LeoLee\Anaconda3\lib\site-packages\sqlalchemy\util\compat.py", line 203, in raise_from_cause
    reraise(type(exception), exception, tb=exc_tb, cause=cause)
  File "C:\LeoLee\Anaconda3\lib\site-packages\sqlalchemy\util\compat.py", line 186, in reraise
    raise value.with_traceback(tb)
  File "C:\LeoLee\Anaconda3\lib\site-packages\sqlalchemy\engine\base.py", line 1114, in _execute_context
    conn = self._revalidate_connection()
  File "C:\LeoLee\Anaconda3\lib\site-packages\sqlalchemy\engine\base.py", line 424, in _revalidate_connection
    "Can't reconnect until invalid "
sqlalchemy.exc.StatementError: (sqlalchemy.exc.InvalidRequestError) Can't reconnect until invalid transaction is rolled back [SQL: 'SELECT `Blog`.blogid AS `Blog_blogid`, `Blog`.title AS `Blog_title`, `Blog`.author AS `Blog_author`, `Blog`.content AS `Blog_content`, `Blog`.sub_date AS `Blog_sub_date`, `Blog`.comment_num AS `Blog_comment_num` \nFROM `Blog` ORDER BY `Blog`.comment_num \n LIMIT %(param_1)s'] [parameters: [{}]]
2019/06/22 23:39:38 - INFO - 87 - _internal - 127.0.0.1 - - [22/Jun/2019 23:39:38] "GET /getRank/ HTTP/1.1" 200 -
2019/06/22 23:39:47 - INFO - 86 - rank - (sqlalchemy.exc.InvalidRequestError) Can't reconnect until invalid transaction is rolled back [SQL: 'SELECT `Blog`.blogid AS `Blog_blogid`, `Blog`.title AS `Blog_title`, `Blog`.author AS `Blog_author`, `Blog`.content AS `Blog_content`, `Blog`.sub_date AS `Blog_sub_date`, `Blog`.comment_num AS `Blog_comment_num` \nFROM `Blog` ORDER BY `Blog`.comment_num \n LIMIT %(param_1)s'] [parameters: [{}]]
Traceback (most recent call last):
  File "C:\LeoLee\Anaconda3\lib\site-packages\sqlalchemy\engine\base.py", line 1112, in _execute_context
    conn = self.__connection
AttributeError: 'Connection' object has no attribute '_Connection__connection'

During handling of the above exception, another exception occurred:

Traceback (most recent call last):
  File "C:\LeoLee\Anaconda3\lib\site-packages\sqlalchemy\engine\base.py", line 1114, in _execute_context
    conn = self._revalidate_connection()
  File "C:\LeoLee\Anaconda3\lib\site-packages\sqlalchemy\engine\base.py", line 424, in _revalidate_connection
    "Can't reconnect until invalid "
sqlalchemy.exc.InvalidRequestError: Can't reconnect until invalid transaction is rolled back

The above exception was the direct cause of the following exception:

Traceback (most recent call last):
  File ".\view\rank.py", line 66, in rankComment
    data = Blog.query.order_by(Blog.comment_num).limit(10).all()
  File "C:\LeoLee\Anaconda3\lib\site-packages\sqlalchemy\orm\query.py", line 2703, in all
    return list(self)
  File "C:\LeoLee\Anaconda3\lib\site-packages\sqlalchemy\orm\query.py", line 2855, in __iter__
    return self._execute_and_instances(context)
  File "C:\LeoLee\Anaconda3\lib\site-packages\sqlalchemy\orm\query.py", line 2878, in _execute_and_instances
    result = conn.execute(querycontext.statement, self._params)
  File "C:\LeoLee\Anaconda3\lib\site-packages\sqlalchemy\engine\base.py", line 945, in execute
    return meth(self, multiparams, params)
  File "C:\LeoLee\Anaconda3\lib\site-packages\sqlalchemy\sql\elements.py", line 263, in _execute_on_connection
    return connection._execute_clauseelement(self, multiparams, params)
  File "C:\LeoLee\Anaconda3\lib\site-packages\sqlalchemy\engine\base.py", line 1053, in _execute_clauseelement
    compiled_sql, distilled_params
  File "C:\LeoLee\Anaconda3\lib\site-packages\sqlalchemy\engine\base.py", line 1121, in _execute_context
    None, None)
  File "C:\LeoLee\Anaconda3\lib\site-packages\sqlalchemy\engine\base.py", line 1402, in _handle_dbapi_exception
    exc_info
  File "C:\LeoLee\Anaconda3\lib\site-packages\sqlalchemy\util\compat.py", line 203, in raise_from_cause
    reraise(type(exception), exception, tb=exc_tb, cause=cause)
  File "C:\LeoLee\Anaconda3\lib\site-packages\sqlalchemy\util\compat.py", line 186, in reraise
    raise value.with_traceback(tb)
  File "C:\LeoLee\Anaconda3\lib\site-packages\sqlalchemy\engine\base.py", line 1114, in _execute_context
    conn = self._revalidate_connection()
  File "C:\LeoLee\Anaconda3\lib\site-packages\sqlalchemy\engine\base.py", line 424, in _revalidate_connection
    "Can't reconnect until invalid "
sqlalchemy.exc.StatementError: (sqlalchemy.exc.InvalidRequestError) Can't reconnect until invalid transaction is rolled back [SQL: 'SELECT `Blog`.blogid AS `Blog_blogid`, `Blog`.title AS `Blog_title`, `Blog`.author AS `Blog_author`, `Blog`.content AS `Blog_content`, `Blog`.sub_date AS `Blog_sub_date`, `Blog`.comment_num AS `Blog_comment_num` \nFROM `Blog` ORDER BY `Blog`.comment_num \n LIMIT %(param_1)s'] [parameters: [{}]]
2019/06/22 23:39:47 - INFO - 87 - _internal - 127.0.0.1 - - [22/Jun/2019 23:39:47] "GET /getRank/ HTTP/1.1" 200 -
2019/06/22 23:39:57 - INFO - 87 - _internal -  * Restarting with stat
2019/06/22 23:39:58 - WARNING - 87 - _internal -  * Debugger is active!
2019/06/22 23:39:58 - INFO - 87 - _internal -  * Debugger PIN: 154-804-553
2019/06/22 23:39:58 - INFO - 87 - _internal -  * Running on http://0.0.0.0:7777/ (Press CTRL+C to quit)
2019/06/22 23:41:31 - INFO - 87 - _internal -  * Restarting with stat
2019/06/22 23:41:32 - WARNING - 87 - _internal -  * Debugger is active!
2019/06/22 23:41:32 - INFO - 87 - _internal -  * Debugger PIN: 154-804-553
2019/06/22 23:41:32 - INFO - 87 - _internal -  * Running on http://0.0.0.0:7777/ (Press CTRL+C to quit)
2019/06/22 23:41:40 - INFO - 87 - _internal - 127.0.0.1 - - [22/Jun/2019 23:41:40] "GET /getRank/ HTTP/1.1" 200 -
2019/06/22 23:42:17 - INFO - 87 - _internal - 127.0.0.1 - - [22/Jun/2019 23:42:17] "GET /getRank/ HTTP/1.1" 200 -
2019/06/22 23:42:47 - INFO - 87 - _internal - 127.0.0.1 - - [22/Jun/2019 23:42:47] "GET /getRank/ HTTP/1.1" 200 -
2019/06/22 23:43:09 - INFO - 87 - _internal - 127.0.0.1 - - [22/Jun/2019 23:43:09] "GET /getRank/ HTTP/1.1" 200 -
2019/06/22 23:43:35 - INFO - 87 - _internal -  * Restarting with stat
2019/06/22 23:43:36 - WARNING - 87 - _internal -  * Debugger is active!
2019/06/22 23:43:36 - INFO - 87 - _internal -  * Debugger PIN: 154-804-553
2019/06/22 23:43:36 - INFO - 87 - _internal -  * Running on http://0.0.0.0:7777/ (Press CTRL+C to quit)
2019/06/22 23:43:40 - INFO - 87 - _internal - 127.0.0.1 - - [22/Jun/2019 23:43:40] "GET /getRank/ HTTP/1.1" 200 -
2019/06/22 23:43:52 - INFO - 87 - _internal -  * Restarting with stat
2019/06/22 23:43:53 - WARNING - 87 - _internal -  * Debugger is active!
2019/06/22 23:43:53 - INFO - 87 - _internal -  * Debugger PIN: 154-804-553
2019/06/22 23:43:53 - INFO - 87 - _internal -  * Running on http://0.0.0.0:7777/ (Press CTRL+C to quit)
2019/06/22 23:44:10 - INFO - 87 - _internal - 127.0.0.1 - - [22/Jun/2019 23:44:10] "GET /getRank/ HTTP/1.1" 200 -
2019/06/22 23:47:12 - INFO - 87 - _internal -  * Restarting with stat
2019/06/22 23:47:13 - WARNING - 87 - _internal -  * Debugger is active!
2019/06/22 23:47:13 - INFO - 87 - _internal -  * Debugger PIN: 154-804-553
2019/06/22 23:47:13 - INFO - 87 - _internal -  * Running on http://0.0.0.0:7777/ (Press CTRL+C to quit)
2019/06/22 23:47:24 - INFO - 87 - _internal - 127.0.0.1 - - [22/Jun/2019 23:47:24] "GET /getRank/ HTTP/1.1" 200 -
